<sdf version='1.6'>
  <world name='empty'>
    <light name='sun' type='directional'>
      <cast_shadows>1</cast_shadows>
      <pose frame=''>0 0 10 0 -0 0</pose>
      <diffuse>0.8 0.8 0.8 1</diffuse>
      <specular>0.2 0.2 0.2 1</specular>
      <attenuation>
        <range>1000</range>
        <constant>0.9</constant>
        <linear>0.01</linear>
        <quadratic>0.001</quadratic>
      </attenuation>
      <direction>-0.5 0.1 -0.9</direction>
    </light>
    <model name='ground_plane'>
      <static>1</static>
      <link name='link'>
        <collision name='collision'>
          <geometry>
            <plane>
              <normal>0 0 1</normal>
              <size>100 100</size>
            </plane>
          </geometry>
          <surface>
            <friction>
              <ode>
                <mu>100</mu>
                <mu2>50</mu2>
              </ode>
              <torsional>
                <ode/>
              </torsional>
            </friction>
            <contact>
              <ode/>
            </contact>
            <bounce/>
          </surface>
          <max_contacts>10</max_contacts>
        </collision>
        <visual name='visual'>
          <cast_shadows>0</cast_shadows>
          <geometry>
            <plane>
              <normal>0 0 1</normal>
              <size>100 100</size>
            </plane>
          </geometry>
          <material>
            <script>
              <uri>file://media/materials/scripts/gazebo.material</uri>
              <name>Gazebo/Grey</name>
            </script>
          </material>
        </visual>
        <self_collide>0</self_collide>
        <enable_wind>0</enable_wind>
        <kinematic>0</kinematic>
      </link>
    </model>
    <physics name='default_physics' default='0' type='ode'>
      <max_step_size>0.001</max_step_size>
      <real_time_factor>1</real_time_factor>
      <real_time_update_rate>1000</real_time_update_rate>
    </physics>
    <model name='coke_can_box_model'>
      <pose frame=''>0.3 0 0.5165 0 -0 0</pose>
      <link name='coke_can'>
        <inertial>
          <mass>1e-15</mass>
          <inertia>
            <ixx>0.00016</ixx>
            <ixy>0</ixy>
            <ixz>0</ixz>
            <iyy>0.00016</iyy>
            <iyz>0</iyz>
            <izz>6e-05</izz>
          </inertia>
          <pose frame=''>0 0 0 0 -0 0</pose>
        </inertial>
        <collision name='collision'>
          <geometry>
            <mesh>
              <uri> model://probot_description/meshes/PROBOT_Anno/TCP.STL</uri>
              <scale>0.24 0.35 0.35</scale>
              </mesh>
            <!-->mesh>
              <uri>model://coke_can/meshes/coke_can.dae</uri>
              <scale>0.24 0.24 0.35</scale>
            </mesh-->
          </geometry>
          <max_contacts>10</max_contacts>
          <surface>
            <friction>
              <ode>
                <mu>100</mu>
                <mu2>100</mu2>
              </ode>
              <torsional>
                <ode/>
              </torsional>
            </friction>
            <contact>
              <ode>
                <kp>1e+06</kp>
                <kd>100</kd>
              </ode>
            </contact>
            <bounce/>
          </surface>
        </collision>
        <visual name='visual'>
          <geometry>
            <mesh>
              <uri>model://coke_can/meshes/coke_can.dae</uri>
              <scale>0.24 0.24 0.35</scale>
            </mesh>
          </geometry>
          <material>
            <script>
              <name>Gazebo/Green</name>
              <uri>file://media/materials/scripts/gazebo.material</uri>
            </script>
          </material>
        </visual>
        <self_collide>0</self_collide>
        <kinematic>0</kinematic>
        <enable_wind>0</enable_wind>
      </link>
    </model>
    <model name='coke_can_box_model_2'>
      <pose frame=''>0.4 0.1 0.2165 0 -0 0</pose>
      <link name='coke_can'>
        <inertial>
          <mass>1e-15</mass>
          <inertia>
            <ixx>0.00016</ixx>
            <ixy>0</ixy>
            <ixz>0</ixz>
            <iyy>0.00016</iyy>
            <iyz>0</iyz>
            <izz>6e-05</izz>
          </inertia>
          <pose frame=''>0 0 0 0 -0 0</pose>
        </inertial>
        <collision name='collision'>
          <geometry>
             <mesh filename="package://probot_description/meshes/PROBOT_Anno/TCP.STL" scale="0.24 0.35 0.35"/>
            <!-->mesh>
              <uri>model://coke_can/meshes/coke_can.dae</uri>
              <scale>0.24 0.24 0.35</scale>
            </mesh-->
          </geometry>
          <max_contacts>10</max_contacts>
          <surface>
            <friction>
              <ode>
                <mu>100</mu>
                <mu2>100</mu2>
              </ode>
              <torsional>
                <ode/>
              </torsional>
            </friction>
            <contact>
              <ode>
                <kp>1e+06</kp>
                <kd>100</kd>
              </ode>
            </contact>
            <bounce/>
          </surface>
        </collision>
        <visual name='visual'>
          <geometry>
             <mesh filename="package://probot_description/meshes/PROBOT_Anno/TCP.STL" scale="0.24 0.24 0.35"/>
            <!-->mesh>
              <uri>model://coke_can/meshes/coke_can.dae</uri>
              <scale>0.24 0.24 0.35</scale>
            </mesh-->
          </geometry>
          <material>
            <script>
              <name>Gazebo/Green</name>
              <uri>file://media/materials/scripts/gazebo.material</uri>
            </script>
          </material>
        </visual>
        <self_collide>0</self_collide>
        <kinematic>0</kinematic>
        <enable_wind>0</enable_wind>
      </link>
    </model>
    <model name='coke_can_box_model_3'>
      <pose frame=''>0.45 0.05 0.207525 -1.69749 1.56223 -1.6974</pose>
      <link name='coke_can'>
        <inertial>
          <mass>1e-15</mass>
          <inertia>
            <ixx>0.00016</ixx>
            <ixy>0</ixy>
            <ixz>0</ixz>
            <iyy>0.00016</iyy>
            <iyz>0</iyz>
            <izz>6e-05</izz>
          </inertia>
          <pose frame=''>0 0 0 0 -0 0</pose>
        </inertial>
        <collision name='collision'>
          <geometry>
             <mesh filename="package://probot_description/meshes/PROBOT_Anno/TCP.STL" scale="0.24 0.24 0.35"/>
            <!-->mesh>
              <uri>model://coke_can/meshes/coke_can.dae</uri>
              <scale>0.24 0.24 0.35</scale>
            </mesh-->
          </geometry>
          <max_contacts>10</max_contacts>
          <surface>
            <friction>
              <ode>
                <mu>100</mu>
                <mu2>100</mu2>
              </ode>
              <torsional>
                <ode/>
              </torsional>
            </friction>
            <contact>
              <ode>
                <kp>1e+06</kp>
                <kd>100</kd>
              </ode>
            </contact>
            <bounce/>
          </surface>
        </collision>
        <visual name='visual'>
          <geometry>
            <mesh>
              <uri>model://coke_can/meshes/coke_can.dae</uri>
              <scale>0.24 0.24 0.35</scale>
            </mesh>
          </geometry>
          <material>
            <script>
              <name>Gazebo/Green</name>
              <uri>file://media/materials/scripts/gazebo.material</uri>
            </script>
          </material>
        </visual>
        <self_collide>0</self_collide>
        <kinematic>0</kinematic>
        <enable_wind>0</enable_wind>
      </link>
    </model>
    <model name='coke_can_box_model_4'>
      <pose frame=''>0.35 0 0.20717 1.57 -0 0</pose>
      <link name='coke_can'>
        <inertial>
          <mass>1e-15</mass>
          <inertia>
            <ixx>0.00016</ixx>
            <ixy>0</ixy>
            <ixz>0</ixz>
            <iyy>0.00016</iyy>
            <iyz>0</iyz>
            <izz>6e-05</izz>
          </inertia>
          <pose frame=''>0 0 0 0 -0 0</pose>
        </inertial>
        <collision name='collision'>
          <geometry>
            <mesh>
              <uri>model://coke_can/meshes/coke_can.dae</uri>
              <scale>0.24 0.24 0.35</scale>
            </mesh>
          </geometry>
          <max_contacts>10</max_contacts>
          <surface>
            <friction>
              <ode>
                <mu>100</mu>
                <mu2>100</mu2>
              </ode>
              <torsional>
                <ode/>
              </torsional>
            </friction>
            <contact>
              <ode>
                <kp>1e+06</kp>
                <kd>100</kd>
              </ode>
            </contact>
            <bounce/>
          </surface>
        </collision>
        <visual name='visual'>
          <geometry>
            <mesh>
              <uri>model://coke_can/meshes/coke_can.dae</uri>
              <scale>0.24 0.24 0.35</scale>
            </mesh>
          </geometry>
          <material>
            <script>
              <name>Gazebo/Green</name>
              <uri>file://media/materials/scripts/gazebo.material</uri>
            </script>
          </material>
        </visual>
        <self_collide>0</self_collide>
        <kinematic>0</kinematic>
        <enable_wind>0</enable_wind>
      </link>
    </model>
    <model name='table_box_model'>
      <static>1</static>
      <pose frame=''>0.4 0 0.1 0 -0 1.5708</pose>
      <link name='table_box_link'>
        <inertial>
          <mass>1</mass>
          <inertia>
            <ixx>0.166667</ixx>
            <ixy>0</ixy>
            <ixz>0</ixz>
            <iyy>0.166667</iyy>
            <iyz>0</iyz>
            <izz>0.166667</izz>
          </inertia>
        </inertial>
        <collision name='collision'>
          <geometry>
            <box>
              <size>0.3 0.3 0.2</size>
            </box>
          </geometry>
          <max_contacts>10</max_contacts>
          <surface>
            <contact>
              <ode/>
            </contact>
            <bounce/>
            <friction>
              <ode>
                <mu>0.6</mu>
                <mu2>0.6</mu2>
              </ode>
              <torsional>
                <ode/>
              </torsional>
            </friction>
          </surface>
        </collision>
        <visual name='visual'>
          <geometry>
            <box>
              <size>0.3 0.3 0.2</size>
            </box>
          </geometry>
          <material>
            <script>
              <name>Gazebo/Black</name>
              <uri>file://media/materials/scripts/gazebo.material</uri>
            </script>
          </material>
        </visual>
        <self_collide>0</self_collide>
        <kinematic>0</kinematic>
        <enable_wind>0</enable_wind>
      </link>
    </model>
    <gravity>0 0 -9.81</gravity>
    <magnetic_field>6e-06 2.3e-05 -4.2e-05</magnetic_field>
    <atmosphere type='adiabatic'/>
    <scene>
      <ambient>0.4 0.4 0.4 1</ambient>
      <background>0.7 0.7 0.7 1</background>
      <shadows>1</shadows>
    </scene>
    <wind/>
    <spherical_coordinates>
      <surface_model>EARTH_WGS84</surface_model>
      <latitude_deg>0</latitude_deg>
      <longitude_deg>0</longitude_deg>
      <elevation>0</elevation>
      <heading_deg>0</heading_deg>
    </spherical_coordinates>
    <model name='probot_anno'>
      <link name='base_link'>
        <pose frame=''>0 0 0 0 -0 0</pose>
        <inertial>
          <pose frame=''>-0.010903 0.231317 0.00522 0 -0 0</pose>
          <mass>0.010001</mass>
          <inertia>
            <ixx>2</ixx>
            <ixy>7.19243e-08</ixy>
            <ixz>-2.16031e-07</ixz>
            <iyy>2</iyy>
            <iyz>1.6073e-07</iyz>
            <izz>2</izz>
          </inertia>
        </inertial>
        <collision name='base_link_collision'>
          <pose frame=''>0.017266 0 0.0315 0 -0 0</pose>
          <geometry>
            <mesh>
              <scale>1 1 1</scale>
              <uri>/home/gjx/orbslam/catkin_ws/src/ZJUBinPicking/probot_description/meshes/PROBOT_Anno/base_link.STL</uri>
            </mesh>
          </geometry>
          <max_contacts>10</max_contacts>
          <surface>
            <contact>
              <ode/>
            </contact>
            <bounce/>
            <friction>
              <torsional>
                <ode/>
              </torsional>
              <ode/>
            </friction>
          </surface>
        </collision>
        <collision name='base_link_fixed_joint_lump__camera_link_collision_1'>
          <pose frame=''>0.3 0 0.7 -3e-06 1.57079 -3e-06</pose>
          <geometry>
            <box>
              <size>0.073 0.276 0.072</size>
            </box>
          </geometry>
          <surface>
            <contact>
              <ode/>
            </contact>
            <friction>
              <ode/>
              <torsional>
                <ode/>
              </torsional>
            </friction>
            <bounce/>
          </surface>
          <max_contacts>10</max_contacts>
        </collision>
        <visual name='base_link_visual'>
          <pose frame=''>0.017266 0 0.0315 0 -0 0</pose>
          <geometry>
            <mesh>
              <scale>1 1 1</scale>
              <uri>/home/gjx/orbslam/catkin_ws/src/ZJUBinPicking/probot_description/meshes/PROBOT_Anno/base_link.STL</uri>
            </mesh>
          </geometry>
        </visual>
        <visual name='base_link_fixed_joint_lump__camera_link_visual_1'>
          <pose frame=''>0.3 0 0.7 -3e-06 1.57079 -3e-06</pose>
          <geometry>
            <mesh>
              <scale>1 1 1</scale>
              <uri>/home/gjx/orbslam/catkin_ws/src/ZJUBinPicking/probot_description/meshes/PROBOT_Anno/kinect.dae</uri>
            </mesh>
          </geometry>
          <material>
            <script>
              <name>Gazebo/Red</name>
              <uri>file://media/materials/scripts/gazebo.material</uri>
            </script>
          </material>
        </visual>
        <gravity>1</gravity>
        <velocity_decay/>
        <sensor name='camera' type='depth'>
          <update_rate>20</update_rate>
          <camera name='__default__'>
            <horizontal_fov>1.0472</horizontal_fov>
            <image>
              <width>640</width>
              <height>480</height>
              <format>R8G8B8</format>
            </image>
            <clip>
              <near>0.05</near>
              <far>3</far>
            </clip>
          </camera>
          <plugin name='camera_plugin' filename='libgazebo_ros_openni_kinect.so'>
            <baseline>0.2</baseline>
            <alwaysOn>true</alwaysOn>
            <updateRate>0.0</updateRate>
            <cameraName>camera_ir</cameraName>
            <imageTopicName>/camera/color/image_raw</imageTopicName>
            <cameraInfoTopicName>/camera/color/camera_info</cameraInfoTopicName>
            <depthImageTopicName>/camera/depth/image_raw</depthImageTopicName>
            <depthImageCameraInfoTopicName>/camera/depth/camera_info</depthImageCameraInfoTopicName>
            <pointCloudTopicName>/camera/depth/points</pointCloudTopicName>
            <frameName>camera_link</frameName>
            <pointCloudCutoff>0</pointCloudCutoff>
            <pointCloudCutoffMax>5.0</pointCloudCutoffMax>
            <distortionK1>0</distortionK1>
            <distortionK2>0</distortionK2>
            <distortionK3>0</distortionK3>
            <distortionT1>0</distortionT1>
            <distortionT2>0</distortionT2>
            <CxPrime>0</CxPrime>
            <Cx>0</Cx>
            <Cy>0</Cy>
            <focalLength>0</focalLength>
            <hackBaseline>0</hackBaseline>
            <robotNamespace>/</robotNamespace>
          </plugin>
          <pose frame=''>0.3 0 0.7 -3e-06 1.57079 -3e-06</pose>
        </sensor>
        <self_collide>0</self_collide>
        <enable_wind>0</enable_wind>
        <kinematic>0</kinematic>
      </link>
      <link name='link_1'>
        <pose frame=''>0 0 0.0315 1.5708 -0 0</pose>
        <inertial>
          <pose frame=''>-0.010934 0.23134 0.005151 0 -0 0</pose>
          <mass>0.01</mass>
          <inertia>
            <ixx>1</ixx>
            <ixy>0</ixy>
            <ixz>0</ixz>
            <iyy>1</iyy>
            <iyz>0</iyz>
            <izz>1</izz>
          </inertia>
        </inertial>
        <collision name='link_1_collision'>
          <pose frame=''>0 0 0 0 -0 0</pose>
          <geometry>
            <mesh>
              <scale>1 1 1</scale>
              <uri>/home/gjx/orbslam/catkin_ws/src/ZJUBinPicking/probot_description/meshes/PROBOT_Anno/link_1.STL</uri>
            </mesh>
          </geometry>
          <max_contacts>10</max_contacts>
          <surface>
            <contact>
              <ode/>
            </contact>
            <bounce/>
            <friction>
              <torsional>
                <ode/>
              </torsional>
              <ode/>
            </friction>
          </surface>
        </collision>
        <visual name='link_1_visual'>
          <pose frame=''>0 0 0 0 -0 0</pose>
          <geometry>
            <mesh>
              <scale>1 1 1</scale>
              <uri>/home/gjx/orbslam/catkin_ws/src/ZJUBinPicking/probot_description/meshes/PROBOT_Anno/link_1.STL</uri>
            </mesh>
          </geometry>
        </visual>
        <self_collide>0</self_collide>
        <enable_wind>0</enable_wind>
        <kinematic>0</kinematic>
      </link>
      <joint name='joint_1' type='revolute'>
        <child>link_1</child>
        <parent>base_link</parent>
        <axis>
          <xyz>0 -4e-06 1</xyz>
          <limit>
            <lower>-3.1416</lower>
            <upper>3.1416</upper>
            <effort>100</effort>
            <velocity>3</velocity>
          </limit>
          <dynamics>
            <spring_reference>0</spring_reference>
            <spring_stiffness>0</spring_stiffness>
          </dynamics>
          <use_parent_model_frame>1</use_parent_model_frame>
        </axis>
      </joint>
      <link name='link_2'>
        <pose frame=''>0 -1e-06 0.262 1.5708 -0 0</pose>
        <inertial>
          <pose frame=''>-0.010934 0.23134 0.005151 0 -0 0</pose>
          <mass>0.001</mass>
          <inertia>
            <ixx>1</ixx>
            <ixy>0</ixy>
            <ixz>0</ixz>
            <iyy>1</iyy>
            <iyz>0</iyz>
            <izz>1</izz>
          </inertia>
        </inertial>
        <collision name='link_2_collision'>
          <pose frame=''>0 0 0 0 -0 0</pose>
          <geometry>
            <mesh>
              <scale>1 1 1</scale>
              <uri>/home/gjx/orbslam/catkin_ws/src/ZJUBinPicking/probot_description/meshes/PROBOT_Anno/link_2.STL</uri>
            </mesh>
          </geometry>
          <max_contacts>10</max_contacts>
          <surface>
            <contact>
              <ode/>
            </contact>
            <bounce/>
            <friction>
              <torsional>
                <ode/>
              </torsional>
              <ode/>
            </friction>
          </surface>
        </collision>
        <visual name='link_2_visual'>
          <pose frame=''>0 0 0 0 -0 0</pose>
          <geometry>
            <mesh>
              <scale>1 1 1</scale>
              <uri>/home/gjx/orbslam/catkin_ws/src/ZJUBinPicking/probot_description/meshes/PROBOT_Anno/link_2.STL</uri>
            </mesh>
          </geometry>
        </visual>
        <self_collide>0</self_collide>
        <enable_wind>0</enable_wind>
        <kinematic>0</kinematic>
      </link>
      <joint name='joint_2' type='revolute'>
        <child>link_2</child>
        <parent>link_1</parent>
        <axis>
          <xyz>0 -1 -4e-06</xyz>
          <limit>
            <lower>-2.0071</lower>
            <upper>2.0071</upper>
            <effort>100</effort>
            <velocity>3</velocity>
          </limit>
          <dynamics>
            <spring_reference>0</spring_reference>
            <spring_stiffness>0</spring_stiffness>
          </dynamics>
          <use_parent_model_frame>1</use_parent_model_frame>
        </axis>
      </joint>
      <link name='link_3'>
        <pose frame=''>0 -2e-06 0.487 1.5708 -0 0</pose>
        <inertial>
          <pose frame=''>-0.010934 0.23134 0.005151 0 -0 0</pose>
          <mass>0.001</mass>
          <inertia>
            <ixx>1</ixx>
            <ixy>0</ixy>
            <ixz>0</ixz>
            <iyy>1</iyy>
            <iyz>0</iyz>
            <izz>1</izz>
          </inertia>
        </inertial>
        <collision name='link_3_collision'>
          <pose frame=''>0 0 0 0 -0 0</pose>
          <geometry>
            <mesh>
              <scale>1 1 1</scale>
              <uri>/home/gjx/orbslam/catkin_ws/src/ZJUBinPicking/probot_description/meshes/PROBOT_Anno/link_3.STL</uri>
            </mesh>
          </geometry>
          <max_contacts>10</max_contacts>
          <surface>
            <contact>
              <ode/>
            </contact>
            <bounce/>
            <friction>
              <torsional>
                <ode/>
              </torsional>
              <ode/>
            </friction>
          </surface>
        </collision>
        <visual name='link_3_visual'>
          <pose frame=''>0 0 0 0 -0 0</pose>
          <geometry>
            <mesh>
              <scale>1 1 1</scale>
              <uri>/home/gjx/orbslam/catkin_ws/src/ZJUBinPicking/probot_description/meshes/PROBOT_Anno/link_3.STL</uri>
            </mesh>
          </geometry>
        </visual>
        <self_collide>0</self_collide>
        <enable_wind>0</enable_wind>
        <kinematic>0</kinematic>
      </link>
      <joint name='joint_3' type='revolute'>
        <child>link_3</child>
        <parent>link_2</parent>
        <axis>
          <xyz>0 -1 -4e-06</xyz>
          <limit>
            <lower>-0.6981</lower>
            <upper>3.8397</upper>
            <effort>100</effort>
            <velocity>3</velocity>
          </limit>
          <dynamics>
            <spring_reference>0</spring_reference>
            <spring_stiffness>0</spring_stiffness>
          </dynamics>
          <use_parent_model_frame>1</use_parent_model_frame>
        </axis>
      </joint>
      <link name='link_4'>
        <pose frame=''>0.023 -2e-06 0.487 1.5708 -0 0</pose>
        <inertial>
          <pose frame=''>-0.010934 0.23134 0.005151 0 -0 0</pose>
          <mass>1e-05</mass>
          <inertia>
            <ixx>1</ixx>
            <ixy>0</ixy>
            <ixz>0</ixz>
            <iyy>1</iyy>
            <iyz>0</iyz>
            <izz>1</izz>
          </inertia>
        </inertial>
        <collision name='link_4_collision'>
          <pose frame=''>0 0 0 0 -0 0</pose>
          <geometry>
            <mesh>
              <scale>1 1 1</scale>
              <uri>/home/gjx/orbslam/catkin_ws/src/ZJUBinPicking/probot_description/meshes/PROBOT_Anno/link_4.STL</uri>
            </mesh>
          </geometry>
          <max_contacts>10</max_contacts>
          <surface>
            <contact>
              <ode/>
            </contact>
            <bounce/>
            <friction>
              <torsional>
                <ode/>
              </torsional>
              <ode/>
            </friction>
          </surface>
        </collision>
        <visual name='link_4_visual'>
          <pose frame=''>0 0 0 0 -0 0</pose>
          <geometry>
            <mesh>
              <scale>1 1 1</scale>
              <uri>/home/gjx/orbslam/catkin_ws/src/ZJUBinPicking/probot_description/meshes/PROBOT_Anno/link_4.STL</uri>
            </mesh>
          </geometry>
        </visual>
        <self_collide>0</self_collide>
        <enable_wind>0</enable_wind>
        <kinematic>0</kinematic>
      </link>
      <joint name='joint_4' type='revolute'>
        <child>link_4</child>
        <parent>link_3</parent>
        <axis>
          <xyz>1 0 0</xyz>
          <limit>
            <lower>-3.1416</lower>
            <upper>3.1416</upper>
            <effort>100</effort>
            <velocity>3</velocity>
          </limit>
          <dynamics>
            <spring_reference>0</spring_reference>
            <spring_stiffness>0</spring_stiffness>
          </dynamics>
          <use_parent_model_frame>1</use_parent_model_frame>
        </axis>
      </joint>
      <link name='link_5'>
        <pose frame=''>0.228855 -2e-06 0.487 1.5708 -0 0</pose>
        <inertial>
          <pose frame=''>-0.010934 0.23134 0.005151 0 -0 0</pose>
          <mass>1e-05</mass>
          <inertia>
            <ixx>1</ixx>
            <ixy>0</ixy>
            <ixz>0</ixz>
            <iyy>1</iyy>
            <iyz>0</iyz>
            <izz>1</izz>
          </inertia>
        </inertial>
        <collision name='link_5_collision'>
          <pose frame=''>0 0 0 0 -0 0</pose>
          <geometry>
            <mesh>
              <scale>1 1 1</scale>
              <uri>/home/gjx/orbslam/catkin_ws/src/ZJUBinPicking/probot_description/meshes/PROBOT_Anno/link_5.STL</uri>
            </mesh>
          </geometry>
          <max_contacts>10</max_contacts>
          <surface>
            <contact>
              <ode/>
            </contact>
            <bounce/>
            <friction>
              <torsional>
                <ode/>
              </torsional>
              <ode/>
            </friction>
          </surface>
        </collision>
        <visual name='link_5_visual'>
          <pose frame=''>0 0 0 0 -0 0</pose>
          <geometry>
            <mesh>
              <scale>1 1 1</scale>
              <uri>/home/gjx/orbslam/catkin_ws/src/ZJUBinPicking/probot_description/meshes/PROBOT_Anno/link_5.STL</uri>
            </mesh>
          </geometry>
        </visual>
        <self_collide>0</self_collide>
        <enable_wind>0</enable_wind>
        <kinematic>0</kinematic>
      </link>
      <joint name='joint_5' type='revolute'>
        <child>link_5</child>
        <parent>link_4</parent>
        <axis>
          <xyz>0 -1 -4e-06</xyz>
          <limit>
            <lower>-0.7854</lower>
            <upper>3.927</upper>
            <effort>100</effort>
            <velocity>3</velocity>
          </limit>
          <dynamics>
            <spring_reference>0</spring_reference>
            <spring_stiffness>0</spring_stiffness>
          </dynamics>
          <use_parent_model_frame>1</use_parent_model_frame>
        </axis>
      </joint>
      <link name='link_6'>
        <pose frame=''>0.228855 -2e-06 0.445 1.5708 -0 0</pose>
        <inertial>
          <pose frame=''>-0.002734 0.033085 -0.008712 0 -0 0</pose>
          <mass>4e-05</mass>
          <inertia>
            <ixx>4</ixx>
            <ixy>2.16772e-08</ixy>
            <ixz>1.5158e-09</ixz>
            <iyy>4</iyy>
            <iyz>-3.66459e-08</iyz>
            <izz>4</izz>
          </inertia>
        </inertial>
        <collision name='link_6_collision'>
          <pose frame=''>0 0 0 0 -0 0</pose>
          <geometry>
            <mesh>
              <scale>1 1 1</scale>
              <uri>/home/gjx/orbslam/catkin_ws/src/ZJUBinPicking/probot_description/meshes/PROBOT_Anno/link_6.STL</uri>
            </mesh>
          </geometry>
          <max_contacts>10</max_contacts>
          <surface>
            <contact>
              <ode/>
            </contact>
            <bounce/>
            <friction>
              <torsional>
                <ode/>
              </torsional>
              <ode/>
            </friction>
          </surface>
        </collision>
        <collision name='link_6_fixed_joint_lump__gripper_base_link_collision_1'>
          <pose frame=''>-0 -0.033 0.00259 0 0 -1.5708</pose>
          <geometry>
            <box>
              <size>0.025 0.038 0.04762</size>
            </box>
          </geometry>
          <max_contacts>10</max_contacts>
          <surface>
            <contact>
              <ode/>
            </contact>
            <bounce/>
            <friction>
              <torsional>
                <ode/>
              </torsional>
              <ode/>
            </friction>
          </surface>
        </collision>
        <collision name='link_6_fixed_joint_lump__gripper_link_collision_2'>
          <pose frame=''>-0 -0.033 0.007 -1.5708 -0 -1.5708</pose>
          <geometry>
            <box>
              <size>0.001 0.001 0.001</size>
            </box>
          </geometry>
          <max_contacts>10</max_contacts>
          <surface>
            <contact>
              <ode/>
            </contact>
            <bounce/>
            <friction>
              <torsional>
                <ode/>
              </torsional>
              <ode/>
            </friction>
          </surface>
        </collision>
        <collision name='link_6_fixed_joint_lump__gripper_static_finger_bracket_link_collision_3'>
          <pose frame=''>-0 -0.033 -0.023 -3.14159 3e-06 1.5708</pose>
          <geometry>
            <box>
              <size>0.025 0.038 0.009</size>
            </box>
          </geometry>
          <max_contacts>10</max_contacts>
          <surface>
            <contact>
              <ode/>
            </contact>
            <bounce/>
            <friction>
              <torsional>
                <ode/>
              </torsional>
              <ode/>
            </friction>
          </surface>
        </collision>
        <collision name='link_6_fixed_joint_lump__gripper_static_finger_link_collision_4'>
          <pose frame=''>0 -0.05945 -0.02095 3.14159 -3e-06 -1.57079</pose>
          <geometry>
            <box>
              <size>0.0783 0.03801 0.0193</size>
            </box>
          </geometry>
          <surface>
            <contact>
              <ode>
                <kp>1e+07</kp>
                <kd>1</kd>
                <min_depth>0.001</min_depth>
              </ode>
            </contact>
            <friction>
              <ode>
                <mu>2000</mu>
                <mu2>1000</mu2>
              </ode>
              <torsional>
                <ode/>
              </torsional>
            </friction>
            <bounce/>
          </surface>
          <max_contacts>10</max_contacts>
        </collision>
        <visual name='link_6_visual'>
          <pose frame=''>0 0 0 0 -0 0</pose>
          <geometry>
            <mesh>
              <scale>1 1 1</scale>
              <uri>/home/gjx/orbslam/catkin_ws/src/ZJUBinPicking/probot_description/meshes/PROBOT_Anno/link_6.STL</uri>
            </mesh>
          </geometry>
        </visual>
        <visual name='link_6_fixed_joint_lump__gripper_base_link_visual_1'>
          <pose frame=''>0 -0.033 0.015 0 0 -1.5708</pose>
          <geometry>
            <mesh>
              <scale>0.001 0.001 0.001</scale>
              <uri>/home/gjx/orbslam/catkin_ws/src/ZJUBinPicking/probot_description/meshes/PROBOT_Anno/gripper/ax12.stl</uri>
            </mesh>
          </geometry>
        </visual>
        <visual name='link_6_fixed_joint_lump__gripper_link_visual_2'>
          <pose frame=''>-0 -0.033 0.007 -1.5708 -0 -1.5708</pose>
          <geometry>
            <box>
              <size>0.001 0.001 0.001</size>
            </box>
          </geometry>
        </visual>
        <visual name='link_6_fixed_joint_lump__gripper_static_finger_bracket_link_visual_3'>
          <pose frame=''>-0 -0.033 -0.0275 -3.14159 3e-06 1.5708</pose>
          <geometry>
            <mesh>
              <scale>0.001 0.001 0.001</scale>
              <uri>/home/gjx/orbslam/catkin_ws/src/ZJUBinPicking/probot_description/meshes/PROBOT_Anno/gripper/F3.stl</uri>
            </mesh>
          </geometry>
        </visual>
        <visual name='link_6_fixed_joint_lump__gripper_static_finger_link_visual_4'>
          <pose frame=''>-0 -0.033 -0.0275 3.14159 -3e-06 -1.57079</pose>
          <geometry>
            <mesh>
              <scale>0.001 0.001 0.001</scale>
              <uri>/home/gjx/orbslam/catkin_ws/src/ZJUBinPicking/probot_description/meshes/PROBOT_Anno/gripper/finger.stl</uri>
            </mesh>
          </geometry>
          <material>
            <script>
              <name>Gazebo/Grey</name>
              <uri>file://media/materials/scripts/gazebo.material</uri>
            </script>
          </material>
        </visual>
        <velocity_decay/>
        <velocity_decay/>
        <gravity>1</gravity>
        <velocity_decay/>
        <self_collide>0</self_collide>
        <enable_wind>0</enable_wind>
        <kinematic>0</kinematic>
      </link>
      <joint name='joint_6' type='revolute'>
        <child>link_6</child>
        <parent>link_5</parent>
        <axis>
          <xyz>0 4e-06 -1</xyz>
          <limit>
            <lower>-3.1416</lower>
            <upper>3.1416</upper>
            <effort>100</effort>
            <velocity>3</velocity>
          </limit>
          <dynamics>
            <spring_reference>0</spring_reference>
            <spring_stiffness>0</spring_stiffness>
          </dynamics>
          <use_parent_model_frame>1</use_parent_model_frame>
        </axis>
      </joint>
      <link name='gripper_active_finger_bracket_link'>
        <pose frame=''>0.228855 -0.015001 0.412 -3.14159 1.57079 1.5708</pose>
        <inertial>
          <pose frame=''>0 0 0.01325 0 -0 0</pose>
          <mass>2e-05</mass>
          <inertia>
            <ixx>2</ixx>
            <ixy>0</ixy>
            <ixz>0</ixz>
            <iyy>2</iyy>
            <iyz>0</iyz>
            <izz>2</izz>
          </inertia>
        </inertial>
        <collision name='gripper_active_finger_bracket_link_collision'>
          <pose frame=''>0 0 0.00775 0 -0 0</pose>
          <geometry>
            <box>
              <size>0.025 0.0485 0.0375</size>
            </box>
          </geometry>
          <max_contacts>10</max_contacts>
          <surface>
            <contact>
              <ode/>
            </contact>
            <bounce/>
            <friction>
              <torsional>
                <ode/>
              </torsional>
              <ode/>
            </friction>
          </surface>
        </collision>
        <collision name='gripper_active_finger_bracket_link_fixed_joint_lump__gripper_active_finger_link_collision_1'>
          <pose frame=''>0.02645 0 0.01995 0 -0 0</pose>
          <geometry>
            <box>
              <size>0.0783 0.03801 0.0193</size>
            </box>
          </geometry>
          <surface>
            <contact>
              <ode>
                <kp>1e+07</kp>
                <kd>1</kd>
                <min_depth>0.001</min_depth>
              </ode>
            </contact>
            <friction>
              <ode>
                <mu>2000</mu>
                <mu2>1000</mu2>
              </ode>
              <torsional>
                <ode/>
              </torsional>
            </friction>
            <bounce/>
          </surface>
          <max_contacts>10</max_contacts>
        </collision>
        <visual name='gripper_active_finger_bracket_link_visual'>
          <pose frame=''>0 0 0 0 -0 0</pose>
          <geometry>
            <mesh>
              <scale>0.001 0.001 0.001</scale>
              <uri>/home/gjx/orbslam/catkin_ws/src/ZJUBinPicking/probot_description/meshes/PROBOT_Anno/gripper/F2.stl</uri>
            </mesh>
          </geometry>
        </visual>
        <visual name='gripper_active_finger_bracket_link_fixed_joint_lump__gripper_active_finger_link_visual_1'>
          <pose frame=''>0 0 0.0265 0 -0 0</pose>
          <geometry>
            <mesh>
              <scale>0.001 0.001 0.001</scale>
              <uri>/home/gjx/orbslam/catkin_ws/src/ZJUBinPicking/probot_description/meshes/PROBOT_Anno/gripper/finger.stl</uri>
            </mesh>
          </geometry>
          <material>
            <script>
              <name>Gazebo/Grey</name>
              <uri>file://media/materials/scripts/gazebo.material</uri>
            </script>
          </material>
        </visual>
        <velocity_decay/>
        <velocity_decay/>
        <gravity>1</gravity>
        <velocity_decay/>
        <self_collide>0</self_collide>
        <enable_wind>0</enable_wind>
        <kinematic>0</kinematic>
      </link>
      <joint name='gripper_finger_joint' type='revolute'>
        <child>gripper_active_finger_bracket_link</child>
        <parent>link_6</parent>
        <axis>
          <xyz>1 0 -0</xyz>
          <limit>
            <lower>-0.8</lower>
            <upper>0.5</upper>
            <effort>1</effort>
            <velocity>3.14</velocity>
          </limit>
          <dynamics>
            <spring_reference>0</spring_reference>
            <spring_stiffness>0</spring_stiffness>
          </dynamics>
          <use_parent_model_frame>1</use_parent_model_frame>
        </axis>
      </joint>
      <static>0</static>
      <plugin name='gazebo_ros_control' filename='libgazebo_ros_control.so'>
        <robotNamespace>/probot_anno</robotNamespace>
        <robotSimType>gazebo_ros_control/DefaultRobotHWSim</robotSimType>
        <legacyModeNS>true</legacyModeNS>
      </plugin>
      <pose frame=''>0 0 0 0 -0 0</pose>
    </model>
    <state world_name='empty'>
      <sim_time>248 71000000</sim_time>
      <real_time>43 67179073</real_time>
      <wall_time>1589703262 868958247</wall_time>
      <iterations>41940</iterations>
      <model name='coke_can_box_model'>
        <pose frame=''>0.300131 0.104267 0.136089 -0.017548 0.005457 -6.1e-05</pose>
        <scale>1 1 1</scale>
        <link name='coke_can'>
          <pose frame=''>0.300131 0.104267 0.136089 -0.017548 0.005457 -6.1e-05</pose>
          <velocity>0 0 0 0 -0 0</velocity>
          <acceleration>-0 0 -8.00518 0 -0 0</acceleration>
          <wrench>-0 0 -0 0 -0 0</wrench>
        </link>
      </model>
      <model name='coke_can_box_model_2'>
        <pose frame=''>0.400115 0.100447 0.136091 -0.018206 0.004698 -4.4e-05</pose>
        <scale>1 1 1</scale>
        <link name='coke_can'>
          <pose frame=''>0.400115 0.100447 0.136091 -0.018206 0.004698 -4.4e-05</pose>
          <velocity>0 0 0 0 -0 0</velocity>
          <acceleration>-0 0 -8.00518 0 -0 0</acceleration>
          <wrench>-0 0 -0 0 -0 0</wrench>
        </link>
      </model>
      <model name='coke_can_box_model_3'>
        <pose frame=''>0.285241 -0.094487 0.206741 -1.33014 1.56205 -1.33006</pose>
        <scale>1 1 1</scale>
        <link name='coke_can'>
          <pose frame=''>0.285241 -0.094487 0.206741 -1.33014 1.56205 -1.33006</pose>
          <velocity>0 0 0 0 -0 0</velocity>
          <acceleration>-0 0 -8.00518 -0 -0 -0</acceleration>
          <wrench>-0 0 -0 0 -0 0</wrench>
        </link>
      </model>
      <model name='coke_can_box_model_4'>
        <pose frame=''>0.35 0.052215 0.20887 1.56459 -0.002615 -0.398706</pose>
        <scale>1 1 1</scale>
        <link name='coke_can'>
          <pose frame=''>0.35 0.052215 0.20887 1.56459 -0.002615 -0.398706</pose>
          <velocity>0 0 0 0 -0 0</velocity>
          <acceleration>0 0 -8.00518 0 -0 0</acceleration>
          <wrench>0 0 -0 0 -0 0</wrench>
        </link>
      </model>
      <model name='ground_plane'>
        <pose frame=''>0 0 0 0 -0 0</pose>
        <scale>1 1 1</scale>
        <link name='link'>
          <pose frame=''>0 0 0 0 -0 0</pose>
          <velocity>0 0 0 0 -0 0</velocity>
          <acceleration>0 0 0 0 -0 0</acceleration>
          <wrench>0 0 0 0 -0 0</wrench>
        </link>
      </model>
      <model name='probot_anno'>
        <pose frame=''>-3e-06 -0 0.0219 -2e-06 -0 -1e-05</pose>
        <scale>1 1 1</scale>
        <link name='base_link'>
          <pose frame=''>-3e-06 -0 0.0219 -2e-06 -0 -1e-05</pose>
          <velocity>-0 -0 0.006755 0 -3e-06 0</velocity>
          <acceleration>2.4e-05 3e-06 13.5085 0.000314 -0.004151 7e-06</acceleration>
          <wrench>0 0 0.135098 0 -0 0</wrench>
        </link>
        <link name='gripper_active_finger_bracket_link'>
          <pose frame=''>0.200063 -0.178016 0.351894 -1.78913 1.56987 2.9227</pose>
          <velocity>-1e-06 1e-06 0.006718 -3e-06 -3e-06 0</velocity>
          <acceleration>-0.000599 0.000936 6.71821 -0.002836 -0.002947 1e-05</acceleration>
          <wrench>-0 0 0.000134 0 -0 0</wrench>
        </link>
        <link name='link_1'>
          <pose frame=''>-3e-06 0 0.0534 1.5708 1e-06 -0.683564</pose>
          <velocity>0 -1e-06 0.006753 0 -3e-06 0</velocity>
          <acceleration>-0.000473 -0.000751 6.75291 2.6e-05 -0.003327 -3.2e-05</acceleration>
          <wrench>-5e-06 -8e-06 0.067529 0 -0 0</wrench>
        </link>
        <link name='link_2'>
          <pose frame=''>-3e-06 -0 0.2839 1.5708 0.192017 -0.683564</pose>
          <velocity>-1e-06 1e-06 0.006749 -1e-06 -3e-06 -0</velocity>
          <acceleration>-0.001672 0.001222 6.74917 -0.000704 -0.003409 -3.2e-05</acceleration>
          <wrench>-2e-06 1e-06 0.006749 0 -0 0</wrench>
        </link>
        <link name='link_3'>
          <pose frame=''>0.033289 -0.027119 0.504765 1.5708 0.347183 -0.683564</pose>
          <velocity>-1e-06 1e-06 0.006748 -1e-06 -3e-06 -0</velocity>
          <acceleration>-0.002148 0.001031 6.74826 -0.001339 -0.003446 -3.2e-05</acceleration>
          <wrench>-2e-06 1e-06 0.006748 0 -0 0</wrench>
        </link>
        <link name='link_4'>
          <pose frame=''>0.050057 -0.040778 0.49694 1.57035 0.347183 -0.683564</pose>
          <velocity>-1e-06 1e-06 0.006754 -2e-06 -3e-06 0</velocity>
          <acceleration>-0.002003 0.00123 6.7539 -0.001806 -0.003167 1e-05</acceleration>
          <wrench>-0 0 6.8e-05 0 -0 0</wrench>
        </link>
        <link name='link_5'>
          <pose frame=''>0.200139 -0.163031 0.426897 1.57038 0.000823 -0.683414</pose>
          <velocity>-1e-06 1e-06 0.006741 -2e-06 -3e-06 0</velocity>
          <acceleration>-0.001674 0.001494 6.74129 -0.002318 -0.003196 1.1e-05</acceleration>
          <wrench>-0 0 6.7e-05 0 -0 0</wrench>
        </link>
        <link name='link_6'>
          <pose frame=''>0.200101 -0.163023 0.384897 1.57099 0.0009 -0.000566</pose>
          <velocity>-1e-06 1e-06 0.006723 -3e-06 -3e-06 0</velocity>
          <acceleration>-0.000814 0.001088 6.72268 -0.00269 -0.002992 1e-05</acceleration>
          <wrench>-0 0 0.000269 0 -0 0</wrench>
        </link>
      </model>
      <model name='table_box_model'>
        <pose frame=''>0.369728 0.00873 0.1 0 -0 1.5708</pose>
        <scale>1 1 1</scale>
        <link name='table_box_link'>
          <pose frame=''>0.369728 0.00873 0.1 0 -0 1.5708</pose>
          <velocity>0 0 0 0 -0 0</velocity>
          <acceleration>0 0 0 0 -0 0</acceleration>
          <wrench>0 0 0 0 -0 0</wrench>
        </link>
      </model>
      <light name='sun'>
        <pose frame=''>0 0 10 0 -0 0</pose>
      </light>
    </state>
    <gui fullscreen='0'>
      <camera name='user_camera'>
        <pose frame=''>1.33751 -0.175437 0.717973 0 0.583643 2.75218</pose>
        <view_controller>orbit</view_controller>
        <projection_type>perspective</projection_type>
      </camera>
    </gui>
  </world>
</sdf>
