
<sdf version='1.6'>
  <world name='empty'>
    <light name='sun' type='directional'>
      <cast_shadows>1</cast_shadows>
      <pose frame=''>0 0 10 0 -0 0</pose>
      <diffuse>0.8 0.8 0.8 1</diffuse>
      <specular>0.2 0.2 0.2 1</specular>
      <attenuation>
        <range>1000</range>
        <constant>0.9</constant>
        <linear>0.01</linear>
        <quadratic>0.001</quadratic>
      </attenuation>
      <direction>-0.5 0.1 -0.9</direction>
    </light>
    <model name='ground_plane'>
      <static>1</static>
      <link name='link'>
        <collision name='collision'>
          <geometry>
            <plane>
              <normal>0 0 1</normal>
              <size>100 100</size>
            </plane>
          </geometry>
          <surface>
            <friction>
              <ode>
                <mu>100</mu>
                <mu2>50</mu2>
              </ode>
              <torsional>
                <ode/>
              </torsional>
            </friction>
            <contact>
              <ode/>
            </contact>
            <bounce/>
          </surface>
          <max_contacts>10</max_contacts>
        </collision>
        <visual name='visual'>
          <cast_shadows>0</cast_shadows>
          <geometry>
            <plane>
              <normal>0 0 1</normal>
              <size>100 100</size>
            </plane>
          </geometry>
          <material>
            <script>
              <uri>file://media/materials/scripts/gazebo.material</uri>
              <name>Gazebo/Grey</name>
            </script>
          </material>
        </visual>
        <self_collide>0</self_collide>
        <enable_wind>0</enable_wind>
        <kinematic>0</kinematic>
      </link>
    </model>
    <physics name='default_physics' default='0' type='ode'>
      <max_step_size>0.001</max_step_size>
      <real_time_factor>1</real_time_factor>
      <real_time_update_rate>1000</real_time_update_rate>
    </physics>
    <model name='coke_can_box_model_3'>
      <pose frame=''>0.45 0.05 0.207525 -1.69749 1.56223 -1.6974</pose>
      <link name='coke_can'>
        <inertial>
          <mass>1e-15</mass>
          <inertia>
            <ixx>0.00016</ixx>
            <ixy>0</ixy>
            <ixz>0</ixz>
            <iyy>0.00016</iyy>
            <iyz>0</iyz>
            <izz>6e-05</izz>
          </inertia>
          <pose frame=''>0 0 0 0 -0 0</pose>
        </inertial>
        <collision name='collision'>
          <geometry>
            <mesh>
              <uri>model://coke_can/meshes/coke_can.dae</uri>
              <scale>0.24 0.24 0.35</scale>
            </mesh>
          </geometry>
          <max_contacts>10</max_contacts>
          <surface>
            <friction>
              <ode>
                <mu>100</mu>
                <mu2>100</mu2>
              </ode>
              <torsional>
                <ode/>
              </torsional>
            </friction>
            <contact>
              <ode>
                <kp>1e+06</kp>
                <kd>100</kd>
              </ode>
            </contact>
            <bounce/>
          </surface>
        </collision>
        <visual name='visual'>
          <geometry>
            <mesh>
              <uri>model://coke_can/meshes/coke_can.dae</uri>
              <scale>0.24 0.24 0.35</scale>
            </mesh>
          </geometry>
          <material>
            <script>
              <name>Gazebo/Green</name>
              <uri>file://media/materials/scripts/gazebo.material</uri>
            </script>
          </material>
        </visual>
        <self_collide>0</self_collide>
        <kinematic>0</kinematic>
        <enable_wind>0</enable_wind>
      </link>
    </model>
    <model name='table_box_model'>
      <static>1</static>
      <pose frame=''>0.4 0 0.1 0 -0 1.5708</pose>
      <link name='table_box_link'>
        <inertial>
          <mass>1</mass>
          <inertia>
            <ixx>0.166667</ixx>
            <ixy>0</ixy>
            <ixz>0</ixz>
            <iyy>0.166667</iyy>
            <iyz>0</iyz>
            <izz>0.166667</izz>
          </inertia>
        </inertial>
        <collision name='collision'>
          <geometry>
            <box>
              <size>0.3 0.3 0.2</size>
            </box>
          </geometry>
          <max_contacts>10</max_contacts>
          <surface>
            <contact>
              <ode/>
            </contact>
            <bounce/>
            <friction>
              <ode>
                <mu>0.6</mu>
                <mu2>0.6</mu2>
              </ode>
              <torsional>
                <ode/>
              </torsional>
            </friction>
          </surface>
        </collision>
        <visual name='visual'>
          <geometry>
            <box>
              <size>0.3 0.3 0.2</size>
            </box>
          </geometry>
          <material>
            <script>
              <name>Gazebo/Black</name>
              <uri>file://media/materials/scripts/gazebo.material</uri>
            </script>
          </material>
        </visual>
        <self_collide>0</self_collide>
        <kinematic>0</kinematic>
        <enable_wind>0</enable_wind>
      </link>
    </model>
    <gravity>0 0 -9.81</gravity>
    <magnetic_field>6e-06 2.3e-05 -4.2e-05</magnetic_field>
    <atmosphere type='adiabatic'/>
    <scene>
      <ambient>0.4 0.4 0.4 1</ambient>
      <background>0.7 0.7 0.7 1</background>
      <shadows>1</shadows>
    </scene>
    <wind/>
    <spherical_coordinates>
      <surface_model>EARTH_WGS84</surface_model>
      <latitude_deg>0</latitude_deg>
      <longitude_deg>0</longitude_deg>
      <elevation>0</elevation>
      <heading_deg>0</heading_deg>
    </spherical_coordinates>
    <model name='probot_anno'>
      <link name='base_link'>
        <pose frame=''>0 0 0 0 -0 0</pose>
        <inertial>
          <pose frame=''>-0.010903 0.231317 0.00522 0 -0 0</pose>
          <mass>0.010001</mass>
          <inertia>
            <ixx>2</ixx>
            <ixy>7.19243e-08</ixy>
            <ixz>-2.16031e-07</ixz>
            <iyy>2</iyy>
            <iyz>1.6073e-07</iyz>
            <izz>2</izz>
          </inertia>
        </inertial>
        <collision name='base_link_collision'>
          <pose frame=''>0.017266 0 0.0315 0 -0 0</pose>
          <geometry>
            <mesh>
              <scale>1 1 1</scale>
              <uri>/home/gjx/orbslam/catkin_ws/src/ZJUBinPicking/probot_description/meshes/PROBOT_Anno/base_link.STL</uri>
            </mesh>
          </geometry>
          <max_contacts>10</max_contacts>
          <surface>
            <contact>
              <ode/>
            </contact>
            <bounce/>
            <friction>
              <torsional>
                <ode/>
              </torsional>
              <ode/>
            </friction>
          </surface>
        </collision>
        <collision name='base_link_fixed_joint_lump__camera_link_collision_1'>
          <pose frame=''>0.3 0 0.7 -3e-06 1.57079 -3e-06</pose>
          <geometry>
            <box>
              <size>0.073 0.276 0.072</size>
            </box>
          </geometry>
          <surface>
            <contact>
              <ode/>
            </contact>
            <friction>
              <ode/>
              <torsional>
                <ode/>
              </torsional>
            </friction>
            <bounce/>
          </surface>
          <max_contacts>10</max_contacts>
        </collision>
        <visual name='base_link_visual'>
          <pose frame=''>0.017266 0 0.0315 0 -0 0</pose>
          <geometry>
            <mesh>
              <scale>1 1 1</scale>
              <uri>/home/gjx/orbslam/catkin_ws/src/ZJUBinPicking/probot_description/meshes/PROBOT_Anno/base_link.STL</uri>
            </mesh>
          </geometry>
        </visual>
        <visual name='base_link_fixed_joint_lump__camera_link_visual_1'>
          <pose frame=''>0.3 0 0.7 -3e-06 1.57079 -3e-06</pose>
          <geometry>
            <mesh>
              <scale>1 1 1</scale>
              <uri>/home/gjx/orbslam/catkin_ws/src/ZJUBinPicking/probot_description/meshes/PROBOT_Anno/kinect.dae</uri>
            </mesh>
          </geometry>
          <material>
            <script>
              <name>Gazebo/Red</name>
              <uri>file://media/materials/scripts/gazebo.material</uri>
            </script>
          </material>
        </visual>
        <gravity>1</gravity>
        <velocity_decay/>
        <sensor name='camera' type='depth'>
          <update_rate>20</update_rate>
          <camera name='__default__'>
            <horizontal_fov>1.0472</horizontal_fov>
            <image>
              <width>640</width>
              <height>480</height>
              <format>R8G8B8</format>
            </image>
            <clip>
              <near>0.05</near>
              <far>3</far>
            </clip>
          </camera>
          <plugin name='camera_plugin' filename='libgazebo_ros_openni_kinect.so'>
            <baseline>0.2</baseline>
            <alwaysOn>true</alwaysOn>
            <updateRate>0.0</updateRate>
            <cameraName>camera_ir</cameraName>
            <imageTopicName>/camera/color/image_raw</imageTopicName>
            <cameraInfoTopicName>/camera/color/camera_info</cameraInfoTopicName>
            <depthImageTopicName>/camera/depth/image_raw</depthImageTopicName>
            <depthImageCameraInfoTopicName>/camera/depth/camera_info</depthImageCameraInfoTopicName>
            <pointCloudTopicName>/camera/depth/points</pointCloudTopicName>
            <frameName>camera_link</frameName>
            <pointCloudCutoff>0</pointCloudCutoff>
            <pointCloudCutoffMax>5.0</pointCloudCutoffMax>
            <distortionK1>0</distortionK1>
            <distortionK2>0</distortionK2>
            <distortionK3>0</distortionK3>
            <distortionT1>0</distortionT1>
            <distortionT2>0</distortionT2>
            <CxPrime>0</CxPrime>
            <Cx>0</Cx>
            <Cy>0</Cy>
            <focalLength>0</focalLength>
            <hackBaseline>0</hackBaseline>
            <robotNamespace>/</robotNamespace>
          </plugin>
          <pose frame=''>0.3 0 0.7 -3e-06 1.57079 -3e-06</pose>
        </sensor>
        <self_collide>0</self_collide>
        <enable_wind>0</enable_wind>
        <kinematic>0</kinematic>
      </link>
      <link name='link_1'>
        <pose frame=''>0 0 0.0315 1.5708 -0 0</pose>
        <inertial>
          <pose frame=''>-0.010934 0.23134 0.005151 0 -0 0</pose>
          <mass>0.01</mass>
          <inertia>
            <ixx>1</ixx>
            <ixy>0</ixy>
            <ixz>0</ixz>
            <iyy>1</iyy>
            <iyz>0</iyz>
            <izz>1</izz>
          </inertia>
        </inertial>
        <collision name='link_1_collision'>
          <pose frame=''>0 0 0 0 -0 0</pose>
          <geometry>
            <mesh>
              <scale>1 1 1</scale>
              <uri>/home/gjx/orbslam/catkin_ws/src/ZJUBinPicking/probot_description/meshes/PROBOT_Anno/link_1.STL</uri>
            </mesh>
          </geometry>
          <max_contacts>10</max_contacts>
          <surface>
            <contact>
              <ode/>
            </contact>
            <bounce/>
            <friction>
              <torsional>
                <ode/>
              </torsional>
              <ode/>
            </friction>
          </surface>
        </collision>
        <visual name='link_1_visual'>
          <pose frame=''>0 0 0 0 -0 0</pose>
          <geometry>
            <mesh>
              <scale>1 1 1</scale>
              <uri>/home/gjx/orbslam/catkin_ws/src/ZJUBinPicking/probot_description/meshes/PROBOT_Anno/link_1.STL</uri>
            </mesh>
          </geometry>
        </visual>
        <self_collide>0</self_collide>
        <enable_wind>0</enable_wind>
        <kinematic>0</kinematic>
      </link>
      <joint name='joint_1' type='revolute'>
        <child>link_1</child>
        <parent>base_link</parent>
        <axis>
          <xyz>0 -4e-06 1</xyz>
          <limit>
            <lower>-3.1416</lower>
            <upper>3.1416</upper>
            <effort>100</effort>
            <velocity>3</velocity>
          </limit>
          <dynamics>
            <spring_reference>0</spring_reference>
            <spring_stiffness>0</spring_stiffness>
          </dynamics>
          <use_parent_model_frame>1</use_parent_model_frame>
        </axis>
      </joint>
      <link name='link_2'>
        <pose frame=''>0 -1e-06 0.262 1.5708 -0 0</pose>
        <inertial>
          <pose frame=''>-0.010934 0.23134 0.005151 0 -0 0</pose>
          <mass>0.001</mass>
          <inertia>
            <ixx>1</ixx>
            <ixy>0</ixy>
            <ixz>0</ixz>
            <iyy>1</iyy>
            <iyz>0</iyz>
            <izz>1</izz>
          </inertia>
        </inertial>
        <collision name='link_2_collision'>
          <pose frame=''>0 0 0 0 -0 0</pose>
          <geometry>
            <mesh>
              <scale>1 1 1</scale>
              <uri>/home/gjx/orbslam/catkin_ws/src/ZJUBinPicking/probot_description/meshes/PROBOT_Anno/link_2.STL</uri>
            </mesh>
          </geometry>
          <max_contacts>10</max_contacts>
          <surface>
            <contact>
              <ode/>
            </contact>
            <bounce/>
            <friction>
              <torsional>
                <ode/>
              </torsional>
              <ode/>
            </friction>
          </surface>
        </collision>
        <visual name='link_2_visual'>
          <pose frame=''>0 0 0 0 -0 0</pose>
          <geometry>
            <mesh>
              <scale>1 1 1</scale>
              <uri>/home/gjx/orbslam/catkin_ws/src/ZJUBinPicking/probot_description/meshes/PROBOT_Anno/link_2.STL</uri>
            </mesh>
          </geometry>
        </visual>
        <self_collide>0</self_collide>
        <enable_wind>0</enable_wind>
        <kinematic>0</kinematic>
      </link>
      <joint name='joint_2' type='revolute'>
        <child>link_2</child>
        <parent>link_1</parent>
        <axis>
          <xyz>0 -1 -4e-06</xyz>
          <limit>
            <lower>-2.0071</lower>
            <upper>2.0071</upper>
            <effort>100</effort>
            <velocity>3</velocity>
          </limit>
          <dynamics>
            <spring_reference>0</spring_reference>
            <spring_stiffness>0</spring_stiffness>
          </dynamics>
          <use_parent_model_frame>1</use_parent_model_frame>
        </axis>
      </joint>
      <link name='link_3'>
        <pose frame=''>0 -2e-06 0.487 1.5708 -0 0</pose>
        <inertial>
          <pose frame=''>-0.010934 0.23134 0.005151 0 -0 0</pose>
          <mass>0.001</mass>
          <inertia>
            <ixx>1</ixx>
            <ixy>0</ixy>
            <ixz>0</ixz>
            <iyy>1</iyy>
            <iyz>0</iyz>
            <izz>1</izz>
          </inertia>
        </inertial>
        <collision name='link_3_collision'>
          <pose frame=''>0 0 0 0 -0 0</pose>
          <geometry>
            <mesh>
              <scale>1 1 1</scale>
              <uri>/home/gjx/orbslam/catkin_ws/src/ZJUBinPicking/probot_description/meshes/PROBOT_Anno/link_3.STL</uri>
            </mesh>
          </geometry>
          <max_contacts>10</max_contacts>
          <surface>
            <contact>
              <ode/>
            </contact>
            <bounce/>
            <friction>
              <torsional>
                <ode/>
              </torsional>
              <ode/>
            </friction>
          </surface>
        </collision>
        <visual name='link_3_visual'>
          <pose frame=''>0 0 0 0 -0 0</pose>
          <geometry>
            <mesh>
              <scale>1 1 1</scale>
              <uri>/home/gjx/orbslam/catkin_ws/src/ZJUBinPicking/probot_description/meshes/PROBOT_Anno/link_3.STL</uri>
            </mesh>
          </geometry>
        </visual>
        <self_collide>0</self_collide>
        <enable_wind>0</enable_wind>
        <kinematic>0</kinematic>
      </link>
      <joint name='joint_3' type='revolute'>
        <child>link_3</child>
        <parent>link_2</parent>
        <axis>
          <xyz>0 -1 -4e-06</xyz>
          <limit>
            <lower>-0.6981</lower>
            <upper>3.8397</upper>
            <effort>100</effort>
            <velocity>3</velocity>
          </limit>
          <dynamics>
            <spring_reference>0</spring_reference>
            <spring_stiffness>0</spring_stiffness>
          </dynamics>
          <use_parent_model_frame>1</use_parent_model_frame>
        </axis>
      </joint>
      <link name='link_4'>
        <pose frame=''>0.023 -2e-06 0.487 1.5708 -0 0</pose>
        <inertial>
          <pose frame=''>-0.010934 0.23134 0.005151 0 -0 0</pose>
          <mass>1e-05</mass>
          <inertia>
            <ixx>1</ixx>
            <ixy>0</ixy>
            <ixz>0</ixz>
            <iyy>1</iyy>
            <iyz>0</iyz>
            <izz>1</izz>
          </inertia>
        </inertial>
        <collision name='link_4_collision'>
          <pose frame=''>0 0 0 0 -0 0</pose>
          <geometry>
            <mesh>
              <scale>1 1 1</scale>
              <uri>/home/gjx/orbslam/catkin_ws/src/ZJUBinPicking/probot_description/meshes/PROBOT_Anno/link_4.STL</uri>
            </mesh>
          </geometry>
          <max_contacts>10</max_contacts>
          <surface>
            <contact>
              <ode/>
            </contact>
            <bounce/>
            <friction>
              <torsional>
                <ode/>
              </torsional>
              <ode/>
            </friction>
          </surface>
        </collision>
        <visual name='link_4_visual'>
          <pose frame=''>0 0 0 0 -0 0</pose>
          <geometry>
            <mesh>
              <scale>1 1 1</scale>
              <uri>/home/gjx/orbslam/catkin_ws/src/ZJUBinPicking/probot_description/meshes/PROBOT_Anno/link_4.STL</uri>
            </mesh>
          </geometry>
        </visual>
        <self_collide>0</self_collide>
        <enable_wind>0</enable_wind>
        <kinematic>0</kinematic>
      </link>
      <joint name='joint_4' type='revolute'>
        <child>link_4</child>
        <parent>link_3</parent>
        <axis>
          <xyz>1 0 0</xyz>
          <limit>
            <lower>-3.1416</lower>
            <upper>3.1416</upper>
            <effort>100</effort>
            <velocity>3</velocity>
          </limit>
          <dynamics>
            <spring_reference>0</spring_reference>
            <spring_stiffness>0</spring_stiffness>
          </dynamics>
          <use_parent_model_frame>1</use_parent_model_frame>
        </axis>
      </joint>
      <link name='link_5'>
        <pose frame=''>0.228855 -2e-06 0.487 1.5708 -0 0</pose>
        <inertial>
          <pose frame=''>-0.010934 0.23134 0.005151 0 -0 0</pose>
          <mass>1e-05</mass>
          <inertia>
            <ixx>1</ixx>
            <ixy>0</ixy>
            <ixz>0</ixz>
            <iyy>1</iyy>
            <iyz>0</iyz>
            <izz>1</izz>
          </inertia>
        </inertial>
        <collision name='link_5_collision'>
          <pose frame=''>0 0 0 0 -0 0</pose>
          <geometry>
            <mesh>
              <scale>1 1 1</scale>
              <uri>/home/gjx/orbslam/catkin_ws/src/ZJUBinPicking/probot_description/meshes/PROBOT_Anno/link_5.STL</uri>
            </mesh>
          </geometry>
          <max_contacts>10</max_contacts>
          <surface>
            <contact>
              <ode/>
            </contact>
            <bounce/>
            <friction>
              <torsional>
                <ode/>
              </torsional>
              <ode/>
            </friction>
          </surface>
        </collision>
        <visual name='link_5_visual'>
          <pose frame=''>0 0 0 0 -0 0</pose>
          <geometry>
            <mesh>
              <scale>1 1 1</scale>
              <uri>/home/gjx/orbslam/catkin_ws/src/ZJUBinPicking/probot_description/meshes/PROBOT_Anno/link_5.STL</uri>
            </mesh>
          </geometry>
        </visual>
        <self_collide>0</self_collide>
        <enable_wind>0</enable_wind>
        <kinematic>0</kinematic>
      </link>
      <joint name='joint_5' type='revolute'>
        <child>link_5</child>
        <parent>link_4</parent>
        <axis>
          <xyz>0 -1 -4e-06</xyz>
          <limit>
            <lower>-0.7854</lower>
            <upper>3.927</upper>
            <effort>100</effort>
            <velocity>3</velocity>
          </limit>
          <dynamics>
            <spring_reference>0</spring_reference>
            <spring_stiffness>0</spring_stiffness>
          </dynamics>
          <use_parent_model_frame>1</use_parent_model_frame>
        </axis>
      </joint>
      <link name='link_6'>
        <pose frame=''>0.228855 -2e-06 0.445 1.5708 -0 0</pose>
        <inertial>
          <pose frame=''>-0.002734 0.033085 -0.008712 0 -0 0</pose>
          <mass>4e-05</mass>
          <inertia>
            <ixx>4</ixx>
            <ixy>2.16772e-08</ixy>
            <ixz>1.5158e-09</ixz>
            <iyy>4</iyy>
            <iyz>-3.66459e-08</iyz>
            <izz>4</izz>
          </inertia>
        </inertial>
        <collision name='link_6_collision'>
          <pose frame=''>0 0 0 0 -0 0</pose>
          <geometry>
            <mesh>
              <scale>1 1 1</scale>
              <uri>/home/gjx/orbslam/catkin_ws/src/ZJUBinPicking/probot_description/meshes/PROBOT_Anno/link_6.STL</uri>
            </mesh>
          </geometry>
          <max_contacts>10</max_contacts>
          <surface>
            <contact>
              <ode/>
            </contact>
            <bounce/>
            <friction>
              <torsional>
                <ode/>
              </torsional>
              <ode/>
            </friction>
          </surface>
        </collision>
        <collision name='link_6_fixed_joint_lump__gripper_base_link_collision_1'>
          <pose frame=''>-0 -0.033 0.00259 0 0 -1.5708</pose>
          <geometry>
            <box>
              <size>0.025 0.038 0.04762</size>
            </box>
          </geometry>
          <max_contacts>10</max_contacts>
          <surface>
            <contact>
              <ode/>
            </contact>
            <bounce/>
            <friction>
              <torsional>
                <ode/>
              </torsional>
              <ode/>
            </friction>
          </surface>
        </collision>
        <collision name='link_6_fixed_joint_lump__gripper_link_collision_2'>
          <pose frame=''>-0 -0.033 0.007 -1.5708 -0 -1.5708</pose>
          <geometry>
            <box>
              <size>0.001 0.001 0.001</size>
            </box>
          </geometry>
          <max_contacts>10</max_contacts>
          <surface>
            <contact>
              <ode/>
            </contact>
            <bounce/>
            <friction>
              <torsional>
                <ode/>
              </torsional>
              <ode/>
            </friction>
          </surface>
        </collision>
        <collision name='link_6_fixed_joint_lump__gripper_static_finger_bracket_link_collision_3'>
          <pose frame=''>-0 -0.033 -0.023 -3.14159 3e-06 1.5708</pose>
          <geometry>
            <box>
              <size>0.025 0.038 0.009</size>
            </box>
          </geometry>
          <max_contacts>10</max_contacts>
          <surface>
            <contact>
              <ode/>
            </contact>
            <bounce/>
            <friction>
              <torsional>
                <ode/>
              </torsional>
              <ode/>
            </friction>
          </surface>
        </collision>
        <collision name='link_6_fixed_joint_lump__gripper_static_finger_link_collision_4'>
          <pose frame=''>0 -0.05945 -0.02095 3.14159 -3e-06 -1.57079</pose>
          <geometry>
            <box>
              <size>0.0783 0.03801 0.0193</size>
            </box>
          </geometry>
          <surface>
            <contact>
              <ode>
                <kp>1e+07</kp>
                <kd>1</kd>
                <min_depth>0.001</min_depth>
              </ode>
            </contact>
            <friction>
              <ode>
                <mu>2000</mu>
                <mu2>1000</mu2>
              </ode>
              <torsional>
                <ode/>
              </torsional>
            </friction>
            <bounce/>
          </surface>
          <max_contacts>10</max_contacts>
        </collision>
        <visual name='link_6_visual'>
          <pose frame=''>0 0 0 0 -0 0</pose>
          <geometry>
            <mesh>
              <scale>1 1 1</scale>
              <uri>/home/gjx/orbslam/catkin_ws/src/ZJUBinPicking/probot_description/meshes/PROBOT_Anno/link_6.STL</uri>
            </mesh>
          </geometry>
        </visual>
        <visual name='link_6_fixed_joint_lump__gripper_base_link_visual_1'>
          <pose frame=''>0 -0.033 0.015 0 0 -1.5708</pose>
          <geometry>
            <mesh>
              <scale>0.001 0.001 0.001</scale>
              <uri>/home/gjx/orbslam/catkin_ws/src/ZJUBinPicking/probot_description/meshes/PROBOT_Anno/gripper/ax12.stl</uri>
            </mesh>
          </geometry>
        </visual>
        <visual name='link_6_fixed_joint_lump__gripper_link_visual_2'>
          <pose frame=''>-0 -0.033 0.007 -1.5708 -0 -1.5708</pose>
          <geometry>
            <box>
              <size>0.001 0.001 0.001</size>
            </box>
          </geometry>
        </visual>
        <visual name='link_6_fixed_joint_lump__gripper_static_finger_bracket_link_visual_3'>
          <pose frame=''>-0 -0.033 -0.0275 -3.14159 3e-06 1.5708</pose>
          <geometry>
            <mesh>
              <scale>0.001 0.001 0.001</scale>
              <uri>/home/gjx/orbslam/catkin_ws/src/ZJUBinPicking/probot_description/meshes/PROBOT_Anno/gripper/F3.stl</uri>
            </mesh>
          </geometry>
        </visual>
        <visual name='link_6_fixed_joint_lump__gripper_static_finger_link_visual_4'>
          <pose frame=''>-0 -0.033 -0.0275 3.14159 -3e-06 -1.57079</pose>
          <geometry>
            <mesh>
              <scale>0.001 0.001 0.001</scale>
              <uri>/home/gjx/orbslam/catkin_ws/src/ZJUBinPicking/probot_description/meshes/PROBOT_Anno/gripper/finger.stl</uri>
            </mesh>
          </geometry>
          <material>
            <script>
              <name>Gazebo/Grey</name>
              <uri>file://media/materials/scripts/gazebo.material</uri>
            </script>
          </material>
        </visual>
        <velocity_decay/>
        <velocity_decay/>
        <gravity>1</gravity>
        <velocity_decay/>
        <self_collide>0</self_collide>
        <enable_wind>0</enable_wind>
        <kinematic>0</kinematic>
      </link>
      <joint name='joint_6' type='revolute'>
        <child>link_6</child>
        <parent>link_5</parent>
        <axis>
          <xyz>0 4e-06 -1</xyz>
          <limit>
            <lower>-3.1416</lower>
            <upper>3.1416</upper>
            <effort>100</effort>
            <velocity>3</velocity>
          </limit>
          <dynamics>
            <spring_reference>0</spring_reference>
            <spring_stiffness>0</spring_stiffness>
          </dynamics>
          <use_parent_model_frame>1</use_parent_model_frame>
        </axis>
      </joint>
      <link name='gripper_active_finger_bracket_link'>
        <pose frame=''>0.228855 -0.015001 0.412 -3.14159 1.57079 1.5708</pose>
        <inertial>
          <pose frame=''>0 0 0.01325 0 -0 0</pose>
          <mass>2e-05</mass>
          <inertia>
            <ixx>2</ixx>
            <ixy>0</ixy>
            <ixz>0</ixz>
            <iyy>2</iyy>
            <iyz>0</iyz>
            <izz>2</izz>
          </inertia>
        </inertial>
        <collision name='gripper_active_finger_bracket_link_collision'>
          <pose frame=''>0 0 0.00775 0 -0 0</pose>
          <geometry>
            <box>
              <size>0.025 0.0485 0.0375</size>
            </box>
          </geometry>
          <max_contacts>10</max_contacts>
          <surface>
            <contact>
              <ode/>
            </contact>
            <bounce/>
            <friction>
              <torsional>
                <ode/>
              </torsional>
              <ode/>
            </friction>
          </surface>
        </collision>
        <collision name='gripper_active_finger_bracket_link_fixed_joint_lump__gripper_active_finger_link_collision_1'>
          <pose frame=''>0.02645 0 0.01995 0 -0 0</pose>
          <geometry>
            <box>
              <size>0.0783 0.03801 0.0193</size>
            </box>
          </geometry>
          <surface>
            <contact>
              <ode>
                <kp>1e+07</kp>
                <kd>1</kd>
                <min_depth>0.001</min_depth>
              </ode>
            </contact>
            <friction>
              <ode>
                <mu>2000</mu>
                <mu2>1000</mu2>
              </ode>
              <torsional>
                <ode/>
              </torsional>
            </friction>
            <bounce/>
          </surface>
          <max_contacts>10</max_contacts>
        </collision>
        <visual name='gripper_active_finger_bracket_link_visual'>
          <pose frame=''>0 0 0 0 -0 0</pose>
          <geometry>
            <mesh>
              <scale>0.001 0.001 0.001</scale>
              <uri>/home/gjx/orbslam/catkin_ws/src/ZJUBinPicking/probot_description/meshes/PROBOT_Anno/gripper/F2.stl</uri>
            </mesh>
          </geometry>
        </visual>
        <visual name='gripper_active_finger_bracket_link_fixed_joint_lump__gripper_active_finger_link_visual_1'>
          <pose frame=''>0 0 0.0265 0 -0 0</pose>
          <geometry>
            <mesh>
              <scale>0.001 0.001 0.001</scale>
              <uri>/home/gjx/orbslam/catkin_ws/src/ZJUBinPicking/probot_description/meshes/PROBOT_Anno/gripper/finger.stl</uri>
            </mesh>
          </geometry>
          <material>
            <script>
              <name>Gazebo/Grey</name>
              <uri>file://media/materials/scripts/gazebo.material</uri>
            </script>
          </material>
        </visual>
        <velocity_decay/>
        <velocity_decay/>
        <gravity>1</gravity>
        <velocity_decay/>
        <self_collide>0</self_collide>
        <enable_wind>0</enable_wind>
        <kinematic>0</kinematic>
      </link>
      <joint name='gripper_finger_joint' type='revolute'>
        <child>gripper_active_finger_bracket_link</child>
        <parent>link_6</parent>
        <axis>
          <xyz>1 0 -0</xyz>
          <limit>
            <lower>-0.8</lower>
            <upper>0.5</upper>
            <effort>1</effort>
            <velocity>3.14</velocity>
          </limit>
          <dynamics>
            <spring_reference>0</spring_reference>
            <spring_stiffness>0</spring_stiffness>
          </dynamics>
          <use_parent_model_frame>1</use_parent_model_frame>
        </axis>
      </joint>
      <static>0</static>
      <plugin name='gazebo_ros_control' filename='libgazebo_ros_control.so'>
        <robotNamespace>/probot_anno</robotNamespace>
        <robotSimType>gazebo_ros_control/DefaultRobotHWSim</robotSimType>
        <legacyModeNS>true</legacyModeNS>
      </plugin>
      <pose frame=''>0 0 0 0 -0 0</pose>
    </model>
    <state world_name='empty'>
      <sim_time>774 680000000</sim_time>
      <real_time>26 984136114</real_time>
      <wall_time>1590064843 671416302</wall_time>
      <iterations>24242</iterations>
      <model name='coke_can_box_model_2_clone_0'>
        <pose frame=''>0.312978 0.016396 0.15835 0.240953 0.004698 -4.4e-05</pose>
        <scale>1 1 1</scale>
        <link name='coke_can'>
          <pose frame=''>0.312978 0.016396 0.15835 0.240953 0.004698 -4.4e-05</pose>
          <velocity>0 0 0 0 -0 0</velocity>
          <acceleration>-0 -0 -8.00518 0 -0 0</acceleration>
          <wrench>-0 -0 -0 0 -0 0</wrench>
        </link>
      </model>
      <model name='coke_can_box_model_2_clone_clone'>
        <pose frame=''>0.326055 0.112027 0.136081 -0.018206 0.004698 -4.4e-05</pose>
        <scale>1 1 1</scale>
        <link name='coke_can'>
          <pose frame=''>0.326055 0.112027 0.136081 -0.018206 0.004698 -4.4e-05</pose>
          <velocity>0 0 0 0 -0 0</velocity>
          <acceleration>0 0 -9.81 0 -0 0</acceleration>
          <wrench>0 0 -0 0 -0 0</wrench>
        </link>
      </model>
      <model name='coke_can_box_model_2_clone_clone_clone'>
        <pose frame=''>0.325378 0.114024 0.179359 -0.018206 0.004698 -4.4e-05</pose>
        <scale>1 1 1</scale>
        <link name='coke_can'>
          <pose frame=''>0.325378 0.114024 0.179359 -0.018206 0.004698 -4.4e-05</pose>
          <velocity>0 0 0 0 -0 0</velocity>
          <acceleration>0 0 -9.81 0 -0 0</acceleration>
          <wrench>0 0 -0 0 -0 0</wrench>
        </link>
      </model>
      <model name='coke_can_box_model_2_clone_clone_clone_0'>
        <pose frame=''>0.380177 -0.093061 0.139692 -0.018206 0.004698 -4.4e-05</pose>
        <scale>1 1 1</scale>
        <link name='coke_can'>
          <pose frame=''>0.380177 -0.093061 0.139692 -0.018206 0.004698 -4.4e-05</pose>
          <velocity>0 0 0 0 -0 0</velocity>
          <acceleration>-0 -0 10 0 -0 0</acceleration>
          <wrench>-0 -0 0 0 -0 0</wrench>
        </link>
      </model>
      <model name='coke_can_box_model_2_clone_clone_clone_1'>
        <pose frame=''>0.329476 -0.090617 0.136436 -0.018206 0.004698 -4.4e-05</pose>
        <scale>1 1 1</scale>
        <link name='coke_can'>
          <pose frame=''>0.329476 -0.090617 0.136436 -0.018206 0.004698 -4.4e-05</pose>
          <velocity>0 0 0 0 -0 0</velocity>
          <acceleration>-0.000171 6e-06 10.0002 0 -0 0</acceleration>
          <wrench>-0 0 0 0 -0 0</wrench>
        </link>
      </model>
      <model name='coke_can_box_model_3'>
        <pose frame=''>0.208628 -0.019973 0.206104 -1.33014 1.56205 -1.33006</pose>
        <scale>1 1 1</scale>
        <link name='coke_can'>
          <pose frame=''>0.208628 -0.019973 0.206104 -1.33014 1.56205 -1.33006</pose>
          <velocity>0 0 0 0 -0 0</velocity>
          <acceleration>-0 0 18.5298 -0 -0 -0</acceleration>
          <wrench>-0 0 0 0 -0 0</wrench>
        </link>
      </model>
      <model name='coke_can_box_model_4_clone'>
        <pose frame=''>0.414366 0.006053 0.209756 1.5749 -0.005337 -2.22681</pose>
        <scale>1 1 1</scale>
        <link name='coke_can'>
          <pose frame=''>0.414366 0.006053 0.209756 1.5749 -0.005337 -2.22681</pose>
          <velocity>0 0 0 0 -0 0</velocity>
          <acceleration>0 -0 -7.98553 0 -0 0</acceleration>
          <wrench>0 -0 -0 0 -0 0</wrench>
        </link>
      </model>
      <model name='coke_can_box_model_4_clone_clone'>
        <pose frame=''>0.266923 -0.098356 0.252488 1.57127 0.006718 1.64098</pose>
        <scale>1 1 1</scale>
        <link name='coke_can'>
          <pose frame=''>0.266923 -0.098356 0.252488 1.57127 0.006718 1.64098</pose>
          <velocity>0 0 0 0 -0 0</velocity>
          <acceleration>-0.110303 0.084179 21.8971 0 -0 0</acceleration>
          <wrench>-0 0 0 0 -0 0</wrench>
        </link>
      </model>
      <model name='ground_plane'>
        <pose frame=''>0 0 0 0 -0 0</pose>
        <scale>1 1 1</scale>
        <link name='link'>
          <pose frame=''>0 0 0 0 -0 0</pose>
          <velocity>0 0 0 0 -0 0</velocity>
          <acceleration>0 0 0 0 -0 0</acceleration>
          <wrench>0 0 0 0 -0 0</wrench>
        </link>
      </model>
      <model name='probot_anno'>
        <pose frame=''>-7e-06 -2e-06 0.021894 -2e-06 -0 -3.5e-05</pose>
        <scale>1 1 1</scale>
        <link name='base_link'>
          <pose frame=''>-7e-06 -2e-06 0.021894 -2e-06 -0 -3.5e-05</pose>
          <velocity>-0 -0 -0.006754 0 1e-06 0</velocity>
          <acceleration>-0.000272 -6e-06 -13.5053 -0.000144 -0.004894 5e-06</acceleration>
          <wrench>-3e-06 -0 -0.135067 0 -0 0</wrench>
        </link>
        <link name='gripper_active_finger_bracket_link'>
          <pose frame=''>0.19996 -0.178009 0.351909 -1.10946 1.56995 -2.68113</pose>
          <velocity>1e-06 -1e-06 -0.006717 1e-06 1e-06 0</velocity>
          <acceleration>0.000725 -0.001073 -6.71674 0.001145 0.001061 1.4e-05</acceleration>
          <wrench>0 -0 -0.000134 0 -0 0</wrench>
        </link>
        <link name='link_1'>
          <pose frame=''>-7e-06 -1e-06 0.053394 1.5708 1e-06 -0.683666</pose>
          <velocity>-0 0 -0.006752 0 1e-06 0</velocity>
          <acceleration>0.000163 5.4e-05 -6.7515 0.000118 0.000868 -3.9e-05</acceleration>
          <wrench>2e-06 1e-06 -0.067515 0 -0 0</wrench>
        </link>
        <link name='link_2'>
          <pose frame=''>-8e-06 -2e-06 0.283894 1.5708 0.191518 -0.683666</pose>
          <velocity>-0 1e-06 -0.006748 0 1e-06 0</velocity>
          <acceleration>0.000303 0.00038 -6.74775 0.000261 0.000752 -3.9e-05</acceleration>
          <wrench>0 0 -0.006748 0 -0 0</wrench>
        </link>
        <link name='link_3'>
          <pose frame=''>0.033196 -0.027054 0.50478 1.5708 0.347223 -0.683666</pose>
          <velocity>0 -1e-06 -0.006747 0 1e-06 0</velocity>
          <acceleration>0.000726 -0.000771 -6.74684 0.000404 0.000635 -4e-05</acceleration>
          <wrench>1e-06 -1e-06 -0.006747 0 -0 0</wrench>
        </link>
        <link name='link_4'>
          <pose frame=''>0.049962 -0.040715 0.496953 1.56998 0.347223 -0.683666</pose>
          <velocity>0 -1e-06 -0.006752 1e-06 1e-06 0</velocity>
          <acceleration>0.000839 -0.000926 -6.75244 0.000661 0.000921 1.4e-05</acceleration>
          <wrench>0 -0 -6.8e-05 0 -0 0</wrench>
        </link>
        <link name='link_5'>
          <pose frame=''>0.20003 -0.162981 0.426903 1.57003 0.000347 -0.683388</pose>
          <velocity>1e-06 -1e-06 -0.00674 1e-06 1e-06 0</velocity>
          <acceleration>0.000895 -0.001161 -6.73969 0.000777 0.000827 1.4e-05</acceleration>
          <wrench>0 -0 -6.7e-05 0 -0 0</wrench>
        </link>
        <link name='link_6'>
          <pose frame=''>0.199998 -0.162997 0.384903 1.57042 0.000754 -0.000866</pose>
          <velocity>1e-06 -1e-06 -0.006721 1e-06 1e-06 0</velocity>
          <acceleration>0.000778 -0.001123 -6.72123 0.001145 0.001019 1.4e-05</acceleration>
          <wrench>0 -0 -0.000269 0 -0 0</wrench>
        </link>
      </model>
      <model name='table_box_model'>
        <pose frame=''>0.36966 0.009191 0.1 0 -0 1.5708</pose>
        <scale>1 1 1</scale>
        <link name='table_box_link'>
          <pose frame=''>0.36966 0.009191 0.1 0 -0 1.5708</pose>
          <velocity>0 0 0 0 -0 0</velocity>
          <acceleration>0 0 0 0 -0 0</acceleration>
          <wrench>0 0 0 0 -0 0</wrench>
        </link>
      </model>
      <light name='sun'>
        <pose frame=''>0 0 10 0 -0 0</pose>
      </light>
    </state>
    <gui fullscreen='0'>
      <camera name='user_camera'>
        <pose frame=''>1.02288 0.041314 0.549071 0 0.347642 3.11218</pose>
        <view_controller>orbit</view_controller>
        <projection_type>perspective</projection_type>
      </camera>
    </gui>
    <model name='coke_can_box_model_2_clone_0'>
      <pose frame=''>0.371714 -0.074994 0.136091 -0.018206 0.004698 -4.4e-05</pose>
      <link name='coke_can'>
        <inertial>
          <mass>1e-15</mass>
          <inertia>
            <ixx>0.00016</ixx>
            <ixy>0</ixy>
            <ixz>0</ixz>
            <iyy>0.00016</iyy>
            <iyz>0</iyz>
            <izz>6e-05</izz>
          </inertia>
          <pose frame=''>0 0 0 0 -0 0</pose>
        </inertial>
        <collision name='collision'>
          <geometry>
            <mesh>
              <uri>model://coke_can/meshes/coke_can.dae</uri>
              <scale>0.24 0.24 0.35</scale>
            </mesh>
          </geometry>
          <max_contacts>10</max_contacts>
          <surface>
            <friction>
              <ode>
                <mu>100</mu>
                <mu2>100</mu2>
              </ode>
              <torsional>
                <ode/>
              </torsional>
            </friction>
            <contact>
              <ode>
                <kp>1e+06</kp>
                <kd>100</kd>
              </ode>
            </contact>
            <bounce/>
          </surface>
        </collision>
        <visual name='visual'>
          <geometry>
            <mesh>
              <uri>model://coke_can/meshes/coke_can.dae</uri>
              <scale>0.24 0.24 0.35</scale>
            </mesh>
          </geometry>
          <material>
            <script>
              <name>Gazebo/Green</name>
              <uri>file://media/materials/scripts/gazebo.material</uri>
            </script>
          </material>
        </visual>
        <self_collide>0</self_collide>
        <kinematic>0</kinematic>
        <enable_wind>0</enable_wind>
      </link>
    </model>
    <model name='coke_can_box_model_4_clone'>
      <pose frame=''>0.449959 0.063605 0.20887 1.56459 -0.002615 -0.398706</pose>
      <link name='coke_can'>
        <inertial>
          <mass>1e-15</mass>
          <inertia>
            <ixx>0.00016</ixx>
            <ixy>0</ixy>
            <ixz>0</ixz>
            <iyy>0.00016</iyy>
            <iyz>0</iyz>
            <izz>6e-05</izz>
          </inertia>
          <pose frame=''>0 0 0 0 -0 0</pose>
        </inertial>
        <collision name='collision'>
          <geometry>
            <mesh>
              <uri>model://coke_can/meshes/coke_can.dae</uri>
              <scale>0.24 0.24 0.35</scale>
            </mesh>
          </geometry>
          <max_contacts>10</max_contacts>
          <surface>
            <friction>
              <ode>
                <mu>100</mu>
                <mu2>100</mu2>
              </ode>
              <torsional>
                <ode/>
              </torsional>
            </friction>
            <contact>
              <ode>
                <kp>1e+06</kp>
                <kd>100</kd>
              </ode>
            </contact>
            <bounce/>
          </surface>
        </collision>
        <visual name='visual'>
          <geometry>
            <mesh>
              <uri>model://coke_can/meshes/coke_can.dae</uri>
              <scale>0.24 0.24 0.35</scale>
            </mesh>
          </geometry>
          <material>
            <script>
              <name>Gazebo/Green</name>
              <uri>file://media/materials/scripts/gazebo.material</uri>
            </script>
          </material>
        </visual>
        <self_collide>0</self_collide>
        <kinematic>0</kinematic>
        <enable_wind>0</enable_wind>
      </link>
    </model>
    <model name='coke_can_box_model_2_clone_clone'>
      <pose frame=''>0.341238 0.091544 0.152213 -0.018206 0.004698 -4.4e-05</pose>
      <link name='coke_can'>
        <inertial>
          <mass>1e-15</mass>
          <inertia>
            <ixx>0.00016</ixx>
            <ixy>0</ixy>
            <ixz>0</ixz>
            <iyy>0.00016</iyy>
            <iyz>0</iyz>
            <izz>6e-05</izz>
          </inertia>
          <pose frame=''>0 0 0 0 -0 0</pose>
        </inertial>
        <collision name='collision'>
          <geometry>
            <mesh>
              <uri>model://coke_can/meshes/coke_can.dae</uri>
              <scale>0.24 0.24 0.35</scale>
            </mesh>
          </geometry>
          <max_contacts>10</max_contacts>
          <surface>
            <friction>
              <ode>
                <mu>100</mu>
                <mu2>100</mu2>
              </ode>
              <torsional>
                <ode/>
              </torsional>
            </friction>
            <contact>
              <ode>
                <kp>1e+06</kp>
                <kd>100</kd>
              </ode>
            </contact>
            <bounce/>
          </surface>
        </collision>
        <visual name='visual'>
          <geometry>
            <mesh>
              <uri>model://coke_can/meshes/coke_can.dae</uri>
              <scale>0.24 0.24 0.35</scale>
            </mesh>
          </geometry>
          <material>
            <script>
              <name>Gazebo/Green</name>
              <uri>file://media/materials/scripts/gazebo.material</uri>
            </script>
          </material>
        </visual>
        <self_collide>0</self_collide>
        <kinematic>0</kinematic>
        <enable_wind>0</enable_wind>
      </link>
    </model>
    <model name='coke_can_box_model_2_clone_clone_clone'>
      <pose frame=''>0.320689 0.121123 0.13609 -0.018206 0.004698 -4.4e-05</pose>
      <link name='coke_can'>
        <inertial>
          <mass>1e-15</mass>
          <inertia>
            <ixx>0.00016</ixx>
            <ixy>0</ixy>
            <ixz>0</ixz>
            <iyy>0.00016</iyy>
            <iyz>0</iyz>
            <izz>6e-05</izz>
          </inertia>
          <pose frame=''>0 0 0 0 -0 0</pose>
        </inertial>
        <collision name='collision'>
          <geometry>
            <mesh>
              <uri>model://coke_can/meshes/coke_can.dae</uri>
              <scale>0.24 0.24 0.35</scale>
            </mesh>
          </geometry>
          <max_contacts>10</max_contacts>
          <surface>
            <friction>
              <ode>
                <mu>100</mu>
                <mu2>100</mu2>
              </ode>
              <torsional>
                <ode/>
              </torsional>
            </friction>
            <contact>
              <ode>
                <kp>1e+06</kp>
                <kd>100</kd>
              </ode>
            </contact>
            <bounce/>
          </surface>
        </collision>
        <visual name='visual'>
          <geometry>
            <mesh>
              <uri>model://coke_can/meshes/coke_can.dae</uri>
              <scale>0.24 0.24 0.35</scale>
            </mesh>
          </geometry>
          <material>
            <script>
              <name>Gazebo/Green</name>
              <uri>file://media/materials/scripts/gazebo.material</uri>
            </script>
          </material>
        </visual>
        <self_collide>0</self_collide>
        <kinematic>0</kinematic>
        <enable_wind>0</enable_wind>
      </link>
    </model>
    <model name='coke_can_box_model_2_clone_clone_clone_0'>
      <pose frame=''>0.402426 -0.027106 0.136087 -0.018206 0.004698 -4.4e-05</pose>
      <link name='coke_can'>
        <inertial>
          <mass>1e-15</mass>
          <inertia>
            <ixx>0.00016</ixx>
            <ixy>0</ixy>
            <ixz>0</ixz>
            <iyy>0.00016</iyy>
            <iyz>0</iyz>
            <izz>6e-05</izz>
          </inertia>
          <pose frame=''>0 0 0 0 -0 0</pose>
        </inertial>
        <collision name='collision'>
          <geometry>
            <mesh>
              <uri>model://coke_can/meshes/coke_can.dae</uri>
              <scale>0.24 0.24 0.35</scale>
            </mesh>
          </geometry>
          <max_contacts>10</max_contacts>
          <surface>
            <friction>
              <ode>
                <mu>100</mu>
                <mu2>100</mu2>
              </ode>
              <torsional>
                <ode/>
              </torsional>
            </friction>
            <contact>
              <ode>
                <kp>1e+06</kp>
                <kd>100</kd>
              </ode>
            </contact>
            <bounce/>
          </surface>
        </collision>
        <visual name='visual'>
          <geometry>
            <mesh>
              <uri>model://coke_can/meshes/coke_can.dae</uri>
              <scale>0.24 0.24 0.35</scale>
            </mesh>
          </geometry>
          <material>
            <script>
              <name>Gazebo/Green</name>
              <uri>file://media/materials/scripts/gazebo.material</uri>
            </script>
          </material>
        </visual>
        <self_collide>0</self_collide>
        <kinematic>0</kinematic>
        <enable_wind>0</enable_wind>
      </link>
    </model>
    <model name='coke_can_box_model_2_clone_clone_clone_1'>
      <pose frame=''>0.403255 0.004864 0.136087 -0.018206 0.004698 -4.4e-05</pose>
      <link name='coke_can'>
        <inertial>
          <mass>1e-15</mass>
          <inertia>
            <ixx>0.00016</ixx>
            <ixy>0</ixy>
            <ixz>0</ixz>
            <iyy>0.00016</iyy>
            <iyz>0</iyz>
            <izz>6e-05</izz>
          </inertia>
          <pose frame=''>0 0 0 0 -0 0</pose>
        </inertial>
        <collision name='collision'>
          <geometry>
            <mesh>
              <uri>model://coke_can/meshes/coke_can.dae</uri>
              <scale>0.24 0.24 0.35</scale>
            </mesh>
          </geometry>
          <max_contacts>10</max_contacts>
          <surface>
            <friction>
              <ode>
                <mu>100</mu>
                <mu2>100</mu2>
              </ode>
              <torsional>
                <ode/>
              </torsional>
            </friction>
            <contact>
              <ode>
                <kp>1e+06</kp>
                <kd>100</kd>
              </ode>
            </contact>
            <bounce/>
          </surface>
        </collision>
        <visual name='visual'>
          <geometry>
            <mesh>
              <uri>model://coke_can/meshes/coke_can.dae</uri>
              <scale>0.24 0.24 0.35</scale>
            </mesh>
          </geometry>
          <material>
            <script>
              <name>Gazebo/Green</name>
              <uri>file://media/materials/scripts/gazebo.material</uri>
            </script>
          </material>
        </visual>
        <self_collide>0</self_collide>
        <kinematic>0</kinematic>
        <enable_wind>0</enable_wind>
      </link>
    </model>
    <model name='coke_can_box_model_4_clone_clone'>
      <pose frame=''>0.398383 -0.028629 0.209757 1.5749 -0.005337 -2.22681</pose>
      <link name='coke_can'>
        <inertial>
          <mass>1e-15</mass>
          <inertia>
            <ixx>0.00016</ixx>
            <ixy>0</ixy>
            <ixz>0</ixz>
            <iyy>0.00016</iyy>
            <iyz>0</iyz>
            <izz>6e-05</izz>
          </inertia>
          <pose frame=''>0 0 0 0 -0 0</pose>
        </inertial>
        <collision name='collision'>
          <geometry>
            <mesh>
              <uri>model://coke_can/meshes/coke_can.dae</uri>
              <scale>0.24 0.24 0.35</scale>
            </mesh>
          </geometry>
          <max_contacts>10</max_contacts>
          <surface>
            <friction>
              <ode>
                <mu>100</mu>
                <mu2>100</mu2>
              </ode>
              <torsional>
                <ode/>
              </torsional>
            </friction>
            <contact>
              <ode>
                <kp>1e+06</kp>
                <kd>100</kd>
              </ode>
            </contact>
            <bounce/>
          </surface>
        </collision>
        <visual name='visual'>
          <geometry>
            <mesh>
              <uri>model://coke_can/meshes/coke_can.dae</uri>
              <scale>0.24 0.24 0.35</scale>
            </mesh>
          </geometry>
          <material>
            <script>
              <name>Gazebo/Green</name>
              <uri>file://media/materials/scripts/gazebo.material</uri>
            </script>
          </material>
        </visual>
        <self_collide>0</self_collide>
        <kinematic>0</kinematic>
        <enable_wind>0</enable_wind>
      </link>
    </model>
  </world>
</sdf>
